Workbook

Sheet Investor dashboard
A1: date | B1: net_nav | C1: shares | D1: investor_value | E1: investor_deposit | G1: Choose investor --> | I1: Shonak Khan | J1: William Collard
A2: 45292 | B2: =_xlfn.XLOOKUP(A2,'Fund Management'!A:A,'Fund Management'!E:E) -> 100 | C2: {=_xlfn.XLOOKUP($I$1,'Client Management'!$B$67:$B$92,_xlfn.XLOOKUP(A2,'Client Management'!$D$3:$AB$3,'Client Management'!$D$67:$AB$92))} -> 0 | D2: =B2*C2 -> 0 | E2: {=_xlfn.XLOOKUP($I$1,'Client Management'!$B$37:$B$62,_xlfn.XLOOKUP(A2,'Client Management'!$D$3:$AB$3,'Client Management'!$D$37:$AB$62))} -> 0 | J2: Mashooq Nasser
A3: 45323 | B3: =_xlfn.XLOOKUP(A3,'Fund Management'!A:A,'Fund Management'!E:E) -> 112.96769 | C3: {=_xlfn.XLOOKUP($I$1,'Client Management'!$B$67:$B$92,_xlfn.XLOOKUP(A3,'Client Management'!$D$3:$AB$3,'Client Management'!$D$67:$AB$92))} -> 0 | D3: =B3*C3 -> 0 | E3: {=_xlfn.XLOOKUP($I$1,'Client Management'!$B$37:$B$62,_xlfn.XLOOKUP(A3,'Client Management'!$D$3:$AB$3,'Client Management'!$D$37:$AB$62))} -> 0 | G3: Current Equity | I3: {=LOOKUP(2,1/(D:D<>""),D:D)} -> 141.45797 | J3: Louis Durance
A4: 45352 | B4: =_xlfn.XLOOKUP(A4,'Fund Management'!A:A,'Fund Management'!E:E) -> 114.2172 | C4: {=_xlfn.XLOOKUP($I$1,'Client Management'!$B$67:$B$92,_xlfn.XLOOKUP(A4,'Client Management'!$D$3:$AB$3,'Client Management'!$D$67:$AB$92))} -> 0 | D4: =B4*C4 -> 0 | E4: {=_xlfn.XLOOKUP($I$1,'Client Management'!$B$37:$B$62,_xlfn.XLOOKUP(A4,'Client Management'!$D$3:$AB$3,'Client Management'!$D$37:$AB$62))} -> 0 | G4: Deposits | I4: =SUM(E:E) -> -1162.55 | J4: Alex Grewe
A5: 45383 | B5: =_xlfn.XLOOKUP(A5,'Fund Management'!A:A,'Fund Management'!E:E) -> 107.59832 | C5: {=_xlfn.XLOOKUP($I$1,'Client Management'!$B$67:$B$92,_xlfn.XLOOKUP(A5,'Client Management'!$D$3:$AB$3,'Client Management'!$D$67:$AB$92))} -> 4.9949663 | D5: =B5*C5 -> 537.45 | E5: {=_xlfn.XLOOKUP($I$1,'Client Management'!$B$37:$B$62,_xlfn.XLOOKUP(A5,'Client Management'!$D$3:$AB$3,'Client Management'!$D$37:$AB$62))} -> 537.45 | G5: Shares | I5: {=LOOKUP(2,1/(C:C<>""),C:C)} -> 0.38370564 | J5: Jiani Chen
A6: 45413 | B6: =_xlfn.XLOOKUP(A6,'Fund Management'!A:A,'Fund Management'!E:E) -> 84.44789 | C6: {=_xlfn.XLOOKUP($I$1,'Client Management'!$B$67:$B$92,_xlfn.XLOOKUP(A6,'Client Management'!$D$3:$AB$3,'Client Management'!$D$67:$AB$92))} -> 4.9949663 | D6: =B6*C6 -> 421.81436 | E6: {=_xlfn.XLOOKUP($I$1,'Client Management'!$B$37:$B$62,_xlfn.XLOOKUP(A6,'Client Management'!$D$3:$AB$3,'Client Management'!$D$37:$AB$62))} -> 0 | G6: NAV per shares | I6: {=LOOKUP(2,1/(B:B<>""),B:B)} -> 368.66274 | J6: Alasgar Mammedov
A7: 45444 | B7: =_xlfn.XLOOKUP(A7,'Fund Management'!A:A,'Fund Management'!E:E) -> 77.571343 | C7: {=_xlfn.XLOOKUP($I$1,'Client Management'!$B$67:$B$92,_xlfn.XLOOKUP(A7,'Client Management'!$D$3:$AB$3,'Client Management'!$D$67:$AB$92))} -> 4.9949663 | D7: =B7*C7 -> 387.46624 | E7: {=_xlfn.XLOOKUP($I$1,'Client Management'!$B$37:$B$62,_xlfn.XLOOKUP(A7,'Client Management'!$D$3:$AB$3,'Client Management'!$D$37:$AB$62))} -> 0 | J7: Alex Kush
A8: 45474 | B8: =_xlfn.XLOOKUP(A8,'Fund Management'!A:A,'Fund Management'!E:E) -> 79.742496 | C8: {=_xlfn.XLOOKUP($I$1,'Client Management'!$B$67:$B$92,_xlfn.XLOOKUP(A8,'Client Management'!$D$3:$AB$3,'Client Management'!$D$67:$AB$92))} -> 4.9949663 | D8: =B8*C8 -> 398.31108 | E8: {=_xlfn.XLOOKUP($I$1,'Client Management'!$B$37:$B$62,_xlfn.XLOOKUP(A8,'Client Management'!$D$3:$AB$3,'Client Management'!$D$37:$AB$62))} -> 0 | J8: Pierre-Alexis Maillart
A9: 45505 | B9: =_xlfn.XLOOKUP(A9,'Fund Management'!A:A,'Fund Management'!E:E) -> 80.778785 | C9: {=_xlfn.XLOOKUP($I$1,'Client Management'!$B$67:$B$92,_xlfn.XLOOKUP(A9,'Client Management'!$D$3:$AB$3,'Client Management'!$D$67:$AB$92))} -> 4.9949663 | D9: =B9*C9 -> 403.48731 | E9: {=_xlfn.XLOOKUP($I$1,'Client Management'!$B$37:$B$62,_xlfn.XLOOKUP(A9,'Client Management'!$D$3:$AB$3,'Client Management'!$D$37:$AB$62))} -> 0 | J9: Jeroen Cox
A10: 45536 | B10: =_xlfn.XLOOKUP(A10,'Fund Management'!A:A,'Fund Management'!E:E) -> 84.173435 | C10: {=_xlfn.XLOOKUP($I$1,'Client Management'!$B$67:$B$92,_xlfn.XLOOKUP(A10,'Client Management'!$D$3:$AB$3,'Client Management'!$D$67:$AB$92))} -> 4.9949663 | D10: =B10*C10 -> 420.44347 | E10: {=_xlfn.XLOOKUP($I$1,'Client Management'!$B$37:$B$62,_xlfn.XLOOKUP(A10,'Client Management'!$D$3:$AB$3,'Client Management'!$D$37:$AB$62))} -> 0 | J10: Tristan Collard
A11: 45566 | B11: =_xlfn.XLOOKUP(A11,'Fund Management'!A:A,'Fund Management'!E:E) -> 78.514278 | C11: {=_xlfn.XLOOKUP($I$1,'Client Management'!$B$67:$B$92,_xlfn.XLOOKUP(A11,'Client Management'!$D$3:$AB$3,'Client Management'!$D$67:$AB$92))} -> 4.9949663 | D11: =B11*C11 -> 392.17617 | E11: {=_xlfn.XLOOKUP($I$1,'Client Management'!$B$37:$B$62,_xlfn.XLOOKUP(A11,'Client Management'!$D$3:$AB$3,'Client Management'!$D$37:$AB$62))} -> 0 | J11: Suyash Gyawali
A12: 45597 | B12: =_xlfn.XLOOKUP(A12,'Fund Management'!A:A,'Fund Management'!E:E) -> 124.59079 | C12: {=_xlfn.XLOOKUP($I$1,'Client Management'!$B$67:$B$92,_xlfn.XLOOKUP(A12,'Client Management'!$D$3:$AB$3,'Client Management'!$D$67:$AB$92))} -> 4.9949663 | D12: =B12*C12 -> 622.32681 | E12: {=_xlfn.XLOOKUP($I$1,'Client Management'!$B$37:$B$62,_xlfn.XLOOKUP(A12,'Client Management'!$D$3:$AB$3,'Client Management'!$D$37:$AB$62))} -> 0 | J12: Suren Rana
A13: 45627 | B13: =_xlfn.XLOOKUP(A13,'Fund Management'!A:A,'Fund Management'!E:E) -> 125.34943 | C13: {=_xlfn.XLOOKUP($I$1,'Client Management'!$B$67:$B$92,_xlfn.XLOOKUP(A13,'Client Management'!$D$3:$AB$3,'Client Management'!$D$67:$AB$92))} -> 4.9949663 | D13: =B13*C13 -> 626.11618 | E13: {=_xlfn.XLOOKUP($I$1,'Client Management'!$B$37:$B$62,_xlfn.XLOOKUP(A13,'Client Management'!$D$3:$AB$3,'Client Management'!$D$37:$AB$62))} -> 0 | J13: Mitch Feij
A14: 45658 | B14: =_xlfn.XLOOKUP(A14,'Fund Management'!A:A,'Fund Management'!E:E) -> 129.91485 | C14: {=_xlfn.XLOOKUP($I$1,'Client Management'!$B$67:$B$92,_xlfn.XLOOKUP(A14,'Client Management'!$D$3:$AB$3,'Client Management'!$D$67:$AB$92))} -> 4.9949663 | D14: =B14*C14 -> 648.92029 | E14: {=_xlfn.XLOOKUP($I$1,'Client Management'!$B$37:$B$62,_xlfn.XLOOKUP(A14,'Client Management'!$D$3:$AB$3,'Client Management'!$D$37:$AB$62))} -> 0 | J14: Philipp Dorfner
A15: 45689 | B15: =_xlfn.XLOOKUP(A15,'Fund Management'!A:A,'Fund Management'!E:E) -> 136.47305 | C15: {=_xlfn.XLOOKUP($I$1,'Client Management'!$B$67:$B$92,_xlfn.XLOOKUP(A15,'Client Management'!$D$3:$AB$3,'Client Management'!$D$67:$AB$92))} -> 4.9949663 | D15: =B15*C15 -> 681.67828 | E15: {=_xlfn.XLOOKUP($I$1,'Client Management'!$B$37:$B$62,_xlfn.XLOOKUP(A15,'Client Management'!$D$3:$AB$3,'Client Management'!$D$37:$AB$62))} -> 0 | J15: Karina Lau
A16: 45717 | B16: =_xlfn.XLOOKUP(A16,'Fund Management'!A:A,'Fund Management'!E:E) -> 137.30314 | C16: {=_xlfn.XLOOKUP($I$1,'Client Management'!$B$67:$B$92,_xlfn.XLOOKUP(A16,'Client Management'!$D$3:$AB$3,'Client Management'!$D$67:$AB$92))} -> 4.9949663 | D16: =B16*C16 -> 685.82456 | E16: {=_xlfn.XLOOKUP($I$1,'Client Management'!$B$37:$B$62,_xlfn.XLOOKUP(A16,'Client Management'!$D$3:$AB$3,'Client Management'!$D$37:$AB$62))} -> 0 | J16: Paolo Shamoon
A17: 45748 | B17: =_xlfn.XLOOKUP(A17,'Fund Management'!A:A,'Fund Management'!E:E) -> 147.7603 | C17: {=_xlfn.XLOOKUP($I$1,'Client Management'!$B$67:$B$92,_xlfn.XLOOKUP(A17,'Client Management'!$D$3:$AB$3,'Client Management'!$D$67:$AB$92))} -> 4.9949663 | D17: =B17*C17 -> 738.05771 | E17: {=_xlfn.XLOOKUP($I$1,'Client Management'!$B$37:$B$62,_xlfn.XLOOKUP(A17,'Client Management'!$D$3:$AB$3,'Client Management'!$D$37:$AB$62))} -> 0 | J17: Jeremy Duckert
A18: 45778 | B18: =_xlfn.XLOOKUP(A18,'Fund Management'!A:A,'Fund Management'!E:E) -> 333.70817 | C18: {=_xlfn.XLOOKUP($I$1,'Client Management'!$B$67:$B$92,_xlfn.XLOOKUP(A18,'Client Management'!$D$3:$AB$3,'Client Management'!$D$67:$AB$92))} -> 4.9949663 | D18: =B18*C18 -> 1666.861 | E18: {=_xlfn.XLOOKUP($I$1,'Client Management'!$B$37:$B$62,_xlfn.XLOOKUP(A18,'Client Management'!$D$3:$AB$3,'Client Management'!$D$37:$AB$62))} -> 0 | J18: Casper Adam
... A24: 45962 | B24: =_xlfn.XLOOKUP(A24,'Fund Management'!A:A,'Fund Management'!E:E) -> 368.66274 | C24: {=_xlfn.XLOOKUP($I$1,'Client Management'!$B$67:$B$92,_xlfn.XLOOKUP(A24,'Client Management'!$D$3:$AB$3,'Client Management'!$D$67:$AB$92))} -> 0.38370564 | D24: =B24*C24 -> 141.45797 | E24: {=_xlfn.XLOOKUP($I$1,'Client Management'!$B$37:$B$62,_xlfn.XLOOKUP(A24,'Client Management'!$D$3:$AB$3,'Client Management'!$D$37:$AB$62))} -> -1700 | J24: Shonak Khan
J25: Annette Bruls
J26: Asad Nasser

Sheet Fund Management
A1: Date | B1: Beginning Gross Value | C1: Beginning Net Value | D1: Beginning gross NAV | E1: Beginning net NAV | F1: Realized PnL | G1: Cumulative PnL | H1: Gross Fund Value EOM | I1: Mgmt. Fees | J1: Perf. Fees | K1: Total fees | L1: Cummulative fees | M1: fees paid | N1: available fees | O1: Net Fund Value EOM | P1: Shares | Q1: Gross NAV EOM | R1: Net NAV EOM | S1: Gross Return | T1: Net Return
A2: 45292 | B2: =_xlfn.XLOOKUP(A2,'Client Management'!$D$3:$AB$3,'Client Management'!$D$64:$AB$64) -> 3001.94 | C2: =B2 -> 3001.94 | D2: 100 | E2: 100 | F2: =SUMIFS(Transactions!$C:$C,Transactions!$A:$A,">="&DATE(YEAR($A2),MONTH($A2),1),Transactions!$A:$A,"<="&EOMONTH($A2,0)) -> 493.37068 | G2: =SUM($F$2:F2) -> 493.37068 | H2: =B2+F2 -> 3495.3107 | I2: =(2%/12)*AVERAGE(B2,H2) -> 5.4143756 | J2: =MAX((F2)*20%,0) -> 98.674136 | K2: =I2+J2 -> 104.08851 | L2: =SUM(K$2:$K2) -> 104.08851 | N2: =L2-SUM($M$2:M2) -> 104.08851 | O2: =C2+F2-K2 -> 3391.2222 | P2: =_xlfn.XLOOKUP(A2,'Client Management'!$D$3:$AB$3,'Client Management'!$D$94:$AB$94) -> 30.0194 | Q2: =H2/P2 -> 116.43506 | R2: =O2/P2 -> 112.96769 | S2: =H2/B2 -1 -> 0.16435061 | T2: =O2/B2 -1 -> 0.12967686
A3: 45323 | B3: =H2+_xlfn.XLOOKUP(A3,'Client Management'!$D$3:$AB$3,'Client Management'!$D$64:$AB$64) -> 6934.1607 | C3: =O2+_xlfn.XLOOKUP(A3,'Client Management'!$D$3:$AB$3,'Client Management'!$D$64:$AB$64) -> 6830.0722 | D3: =Q2 -> 116.43506 | E3: =R2 -> 112.96769 | F3: =SUMIFS(Transactions!$C:$C,Transactions!$A:$A,">="&DATE(YEAR($A3),MONTH($A3),1),Transactions!$A:$A,"<="&EOMONTH($A3,0)) -> 108.99225 | G3: =SUM($F$2:F3) -> 602.36292 | H3: =B3+F3 -> 7043.1529 | I3: =(2%/12)*AVERAGE(B3,H3) -> 11.647761 | J3: =MAX((F3)*20%,0) -> 21.798449 | K3: =I3+J3 -> 33.446211 | L3: =SUM(K$2:$K3) -> 137.53472 | N3: =L3-SUM($M$2:M3) -> 137.53472 | O3: =C3+F3-K3 -> 6905.6182 | P3: =_xlfn.XLOOKUP(A3,'Client Management'!$D$3:$AB$3,'Client Management'!$D$94:$AB$94) -> 60.460406 | Q3: =H3/P3 -> 116.49199 | R3: =O3/P3 -> 114.2172 | S3: =H3/B3 -1 -> 0.01571816 | T3: =O3/B3 -1 -> -0.004116212
A4: 45352 | B4: =H3+_xlfn.XLOOKUP(A4,'Client Management'!$D$3:$AB$3,'Client Management'!$D$64:$AB$64) -> 16463.443 | C4: =O3+_xlfn.XLOOKUP(A4,'Client Management'!$D$3:$AB$3,'Client Management'!$D$64:$AB$64) -> 16325.908 | D4: =Q3 -> 116.49199 | E4: =R3 -> 114.2172 | F4: =SUMIFS(Transactions!$C:$C,Transactions!$A:$A,">="&DATE(YEAR($A4),MONTH($A4),1),Transactions!$A:$A,"<="&EOMONTH($A4,0)) -> -919.41183 | G4: =SUM($F$2:F4) -> -317.04891 | H4: =B4+F4 -> 15544.031 | I4: =(2%/12)*AVERAGE(B4,H4) -> 26.672895 | J4: =MAX((F4)*20%,0) -> 0 | K4: =I4+J4 -> 26.672895 | L4: =SUM(K$2:$K4) -> 164.20762 | N4: =L4-SUM($M$2:M4) -> 164.20762 | O4: =C4+F4-K4 -> 15379.823 | P4: =_xlfn.XLOOKUP(A4,'Client Management'!$D$3:$AB$3,'Client Management'!$D$94:$AB$94) -> 142.93739 | Q4: =H4/P4 -> 108.74713 | R4: =O4/P4 -> 107.59832 | S4: =H4/B4 -1 -> -0.05584566 | T4: =O4/B4 -1 -> -0.065819735
A5: 45383 | B5: =H4+_xlfn.XLOOKUP(A5,'Client Management'!$D$3:$AB$3,'Client Management'!$D$64:$AB$64) -> 16081.481 | C5: =O4+_xlfn.XLOOKUP(A5,'Client Management'!$D$3:$AB$3,'Client Management'!$D$64:$AB$64) -> 15917.273 | D5: =Q4 -> 108.74713 | E5: =R4 -> 107.59832 | F5: =SUMIFS(Transactions!$C:$C,Transactions!$A:$A,">="&DATE(YEAR($A5),MONTH($A5),1),Transactions!$A:$A,"<="&EOMONTH($A5,0)) -> -3400.7297 | G5: =SUM($F$2:F5) -> -3717.7786 | H5: =B5+F5 -> 12680.751 | I5: =(2%/12)*AVERAGE(B5,H5) -> 23.968527 | J5: =MAX((F5)*20%,0) -> 0 | K5: =I5+J5 -> 23.968527 | L5: =SUM(K$2:$K5) -> 188.17614 | N5: =L5-SUM($M$2:M5) -> 188.17614 | O5: =C5+F5-K5 -> 12492.575 | P5: =_xlfn.XLOOKUP(A5,'Client Management'!$D$3:$AB$3,'Client Management'!$D$94:$AB$94) -> 147.93236 | Q5: =H5/P5 -> 85.719932 | R5: =O5/P5 -> 84.44789 | S5: =H5/B5 -1 -> -0.21146869 | T5: =O5/B5 -1 -> -0.22317011
A6: 45413 | B6: =H5+_xlfn.XLOOKUP(A6,'Client Management'!$D$3:$AB$3,'Client Management'!$D$64:$AB$64) -> 12680.751 | C6: =O5+_xlfn.XLOOKUP(A6,'Client Management'!$D$3:$AB$3,'Client Management'!$D$64:$AB$64) -> 12492.575 | D6: =Q5 -> 85.719932 | E6: =R5 -> 84.44789 | F6: =SUMIFS(Transactions!$C:$C,Transactions!$A:$A,">="&DATE(YEAR($A6),MONTH($A6),1),Transactions!$A:$A,"<="&EOMONTH($A6,0)) -> -996.96 | G6: =SUM($F$2:F6) -> -4714.7386 | H6: =B6+F6 -> 11683.791 | I6: =(2%/12)*AVERAGE(B6,H6) -> 20.303786 | J6: =MAX((F6)*20%,0) -> 0 | K6: =I6+J6 -> 20.303786 | L6: =SUM(K$2:$K6) -> 208.47993 | N6: =L6-SUM($M$2:M6) -> 208.47993 | O6: =C6+F6-K6 -> 11475.311 | P6: =_xlfn.XLOOKUP(A6,'Client Management'!$D$3:$AB$3,'Client Management'!$D$94:$AB$94) -> 147.93236 | Q6: =H6/P6 -> 78.980635 | R6: =O6/P6 -> 77.571343 | S6: =H6/B6 -1 -> -0.078619947 | T6: =O6/B6 -1 -> -0.095060608
A7: 45444 | B7: =H6+_xlfn.XLOOKUP(A7,'Client Management'!$D$3:$AB$3,'Client Management'!$D$64:$AB$64) -> 13310.091 | C7: =O6+_xlfn.XLOOKUP(A7,'Client Management'!$D$3:$AB$3,'Client Management'!$D$64:$AB$64) -> 13101.611 | D7: =Q6 -> 78.980635 | E7: =R6 -> 77.571343 | F7: =SUMIFS(Transactions!$C:$C,Transactions!$A:$A,">="&DATE(YEAR($A7),MONTH($A7),1),Transactions!$A:$A,"<="&EOMONTH($A7,0)) -> 486.61431 | G7: =SUM($F$2:F7) -> -4228.1243 | H7: =B7+F7 -> 13796.706 | I7: =(2%/12)*AVERAGE(B7,H7) -> 22.588998 | J7: =MAX((F7)*20%,0) -> 97.322862 | K7: =I7+J7 -> 119.91186 | L7: =SUM(K$2:$K7) -> 328.39179 | N7: =L7-SUM($M$2:M7) -> 328.39179 | O7: =C7+F7-K7 -> 13468.314 | P7: =_xlfn.XLOOKUP(A7,'Client Management'!$D$3:$AB$3,'Client Management'!$D$94:$AB$94) -> 168.89757 | Q7: =H7/P7 -> 81.686821 | R7: =O7/P7 -> 79.742496 | S7: =H7/B7 -1 -> 0.036559803 | T7: =O7/B7 -1 -> 0.011887411
A8: 45474 | B8: =H7+_xlfn.XLOOKUP(A8,'Client Management'!$D$3:$AB$3,'Client Management'!$D$64:$AB$64) -> 13796.706 | C8: =O7+_xlfn.XLOOKUP(A8,'Client Management'!$D$3:$AB$3,'Client Management'!$D$64:$AB$64) -> 13468.314 | D8: =Q7 -> 81.686821 | E8: =R7 -> 79.742496 | F8: =SUMIFS(Transactions!$C:$C,Transactions!$A:$A,">="&DATE(YEAR($A8),MONTH($A8),1),Transactions!$A:$A,"<="&EOMONTH($A8,0)) -> 247.78477 | G8: =SUM($F$2:F8) -> -3980.3396 | H8: =B8+F8 -> 14044.49 | I8: =(2%/12)*AVERAGE(B8,H8) -> 23.200997 | J8: =MAX((F8)*20%,0) -> 49.556954 | K8: =I8+J8 -> 72.757951 | L8: =SUM(K$2:$K8) -> 401.14974 | N8: =L8-SUM($M$2:M8) -> 401.14974 | O8: =C8+F8-K8 -> 13643.341 | P8: =_xlfn.XLOOKUP(A8,'Client Management'!$D$3:$AB$3,'Client Management'!$D$94:$AB$94) -> 168.89757 | Q8: =H8/P8 -> 83.153892 | R8: =O8/P8 -> 80.778785 | S8: =H8/B8 -1 -> 0.017959706 | T8: =O8/B8 -1 -> -0.011116057
A9: 45505 | B9: =H8+_xlfn.XLOOKUP(A9,'Client Management'!$D$3:$AB$3,'Client Management'!$D$64:$AB$64) -> 14044.49 | C9: =O8+_xlfn.XLOOKUP(A9,'Client Management'!$D$3:$AB$3,'Client Management'!$D$64:$AB$64) -> 13643.341 | D9: =Q8 -> 83.153892 | E9: =R8 -> 80.778785 | F9: =SUMIFS(Transactions!$C:$C,Transactions!$A:$A,">="&DATE(YEAR($A9),MONTH($A9),1),Transactions!$A:$A,"<="&EOMONTH($A9,0)) -> 746.72236 | G9: =SUM($F$2:F9) -> -3233.6172 | H9: =B9+F9 -> 14791.213 | I9: =(2%/12)*AVERAGE(B9,H9) -> 24.029753 | J9: =MAX((F9)*20%,0) -> 149.34447 | K9: =I9+J9 -> 173.37423 | L9: =SUM(K$2:$K9) -> 574.52397 | N9: =L9-SUM($M$2:M9) -> 574.52397 | O9: =C9+F9-K9 -> 14216.689 | P9: =_xlfn.XLOOKUP(A9,'Client Management'!$D$3:$AB$3,'Client Management'!$D$94:$AB$94) -> 168.89757 | Q9: =H9/P9 -> 87.575047 | R9: =O9/P9 -> 84.173435 | S9: =H9/B9 -1 -> 0.053168348 | T9: =O9/B9 -1 -> 0.012260922
A10: 45536 | B10: =H9+_xlfn.XLOOKUP(A10,'Client Management'!$D$3:$AB$3,'Client Management'!$D$64:$AB$64) -> 14791.213 | C10: =O9+_xlfn.XLOOKUP(A10,'Client Management'!$D$3:$AB$3,'Client Management'!$D$64:$AB$64) -> 14216.689 | D10: =Q9 -> 87.575047 | E10: =R9 -> 84.173435 | F10: =SUMIFS(Transactions!$C:$C,Transactions!$A:$A,">="&DATE(YEAR($A10),MONTH($A10),1),Transactions!$A:$A,"<="&EOMONTH($A10,0)) -> -931.9425 | G10: =SUM($F$2:F10) -> -4165.5597 | H10: =B10+F10 -> 13859.27 | I10: =(2%/12)*AVERAGE(B10,H10) -> 23.875403 | J10: =MAX((F10)*20%,0) -> 0 | K10: =I10+J10 -> 23.875403 | L10: =SUM(K$2:$K10) -> 598.39937 | N10: =L10-SUM($M$2:M10) -> 598.39937 | O10: =C10+F10-K10 -> 13260.871 | P10: =_xlfn.XLOOKUP(A10,'Client Management'!$D$3:$AB$3,'Client Management'!$D$94:$AB$94) -> 168.89757 | Q10: =H10/P10 -> 82.05725 | R10: =O10/P10 -> 78.514278 | S10: =H10/B10 -1 -> -0.063006497 | T10: =O10/B10 -1 -> -0.10346291
A11: 45566 | B11: =H10+_xlfn.XLOOKUP(A11,'Client Management'!$D$3:$AB$3,'Client Management'!$D$64:$AB$64) -> 13859.27 | C11: =O10+_xlfn.XLOOKUP(A11,'Client Management'!$D$3:$AB$3,'Client Management'!$D$64:$AB$64) -> 13260.871 | D11: =Q10 -> 82.05725 | E11: =R10 -> 78.514278 | F11: =SUMIFS(Transactions!$C:$C,Transactions!$A:$A,">="&DATE(YEAR($A11),MONTH($A11),1),Transactions!$A:$A,"<="&EOMONTH($A11,0)) -> 9766.8117 | G11: =SUM($F$2:F11) -> 5601.252 | H11: =B11+F11 -> 23626.082 | I11: =(2%/12)*AVERAGE(B11,H11) -> 31.237794 | J11: =MAX((F11)*20%,0) -> 1953.3623 | K11: =I11+J11 -> 1984.6001 | L11: =SUM(K$2:$K11) -> 2582.9995 | N11: =L11-SUM($M$2:M11) -> 2582.9995 | O11: =C11+F11-K11 -> 21043.083 | P11: =_xlfn.XLOOKUP(A11,'Client Management'!$D$3:$AB$3,'Client Management'!$D$94:$AB$94) -> 168.89757 | Q11: =H11/P11 -> 139.88408 | R11: =O11/P11 -> 124.59079 | S11: =H11/B11 -1 -> 0.70471327 | T11: =O11/B11 -1 -> 0.51833986
A12: 45597 | B12: =H11+_xlfn.XLOOKUP(A12,'Client Management'!$D$3:$AB$3,'Client Management'!$D$64:$AB$64) -> 23626.082 | C12: =O11+_xlfn.XLOOKUP(A12,'Client Management'!$D$3:$AB$3,'Client Management'!$D$64:$AB$64) -> 21043.083 | D12: =Q11 -> 139.88408 | E12: =R11 -> 124.59079 | F12: =SUMIFS(Transactions!$C:$C,Transactions!$A:$A,">="&DATE(YEAR($A12),MONTH($A12),1),Transactions!$A:$A,"<="&EOMONTH($A12,0)) -> 209.60445 | G12: =SUM($F$2:F12) -> 5810.8565 | H12: =B12+F12 -> 23835.686 | I12: =(2%/12)*AVERAGE(B12,H12) -> 39.551474 | J12: =MAX((F12)*20%,0) -> 41.92089 | K12: =I12+J12 -> 81.472364 | L12: =SUM(K$2:$K12) -> 2664.4719 | N12: =L12-SUM($M$2:M12) -> 2664.4719 | O12: =C12+F12-K12 -> 21171.215 | P12: =_xlfn.XLOOKUP(A12,'Client Management'!$D$3:$AB$3,'Client Management'!$D$94:$AB$94) -> 168.89757 | Q12: =H12/P12 -> 141.1251 | R12: =O12/P12 -> 125.34943 | S12: =H12/B12 -1 -> 0.0088717398 | T12: =O12/B12 -1 -> -0.10390497
A13: 45627 | B13: =H12+_xlfn.XLOOKUP(A13,'Client Management'!$D$3:$AB$3,'Client Management'!$D$64:$AB$64) -> 23835.686 | C13: =O12+_xlfn.XLOOKUP(A13,'Client Management'!$D$3:$AB$3,'Client Management'!$D$64:$AB$64) -> 21171.215 | D13: =Q12 -> 141.1251 | E13: =R12 -> 125.34943 | F13: =SUMIFS(Transactions!$C:$C,Transactions!$A:$A,">="&DATE(YEAR($A13),MONTH($A13),1),Transactions!$A:$A,"<="&EOMONTH($A13,0)) -> 1014.5744 | G13: =SUM($F$2:F13) -> 6825.4309 | H13: =B13+F13 -> 24850.261 | I13: =(2%/12)*AVERAGE(B13,H13) -> 40.571623 | J13: =MAX((F13)*20%,0) -> 202.91488 | K13: =I13+J13 -> 243.4865 | L13: =SUM(K$2:$K13) -> 2907.9584 | N13: =L13-SUM($M$2:M13) -> 2907.9584 | O13: =C13+F13-K13 -> 21942.302 | P13: =_xlfn.XLOOKUP(A13,'Client Management'!$D$3:$AB$3,'Client Management'!$D$94:$AB$94) -> 168.89757 | Q13: =H13/P13 -> 147.13214 | R13: =O13/P13 -> 129.91485 | S13: =H13/B13 -1 -> 0.042565352 | T13: =O13/B13 -1 -> -0.079434842
A14: 45658 | B14: =H13+_xlfn.XLOOKUP(A14,'Client Management'!$D$3:$AB$3,'Client Management'!$D$64:$AB$64) -> 24450.101 | C14: =O13+_xlfn.XLOOKUP(A14,'Client Management'!$D$3:$AB$3,'Client Management'!$D$64:$AB$64) -> 21542.142 | D14: =Q13 -> 147.13214 | E14: =R13 -> 129.91485 | F14: =SUMIFS(Transactions!$C:$C,Transactions!$A:$A,">="&DATE(YEAR($A14),MONTH($A14),1),Transactions!$A:$A,"<="&EOMONTH($A14,0)) -> 1411.7379 | G14: =SUM($F$2:F14) -> 8237.1688 | H14: =B14+F14 -> 25861.839 | I14: =(2%/12)*AVERAGE(B14,H14) -> 41.926616 | J14: =MAX((F14)*20%,0) -> 282.34759 | K14: =I14+J14 -> 324.2742 | L14: =SUM(K$2:$K14) -> 3232.2326 | N14: =L14-SUM($M$2:M14) -> 3232.2326 | O14: =C14+F14-K14 -> 22629.606 | P14: =_xlfn.XLOOKUP(A14,'Client Management'!$D$3:$AB$3,'Client Management'!$D$94:$AB$94) -> 165.8174 | Q14: =H14/P14 -> 155.96577 | R14: =O14/P14 -> 136.47305 | S14: =H14/B14 -1 -> 0.057739555 | T14: =O14/B14 -1 -> -0.074457551
... A24: 45962 | B24: =H23+_xlfn.XLOOKUP(A24,'Client Management'!$D$3:$AB$3,'Client Management'!$D$64:$AB$64) -> 87613.899 | C24: =O23+_xlfn.XLOOKUP(A24,'Client Management'!$D$3:$AB$3,'Client Management'!$D$64:$AB$64) -> 72654.966 | D24: =Q23 -> 442.83131 | E24: =R23 -> 368.66274 | F24: =SUMIFS(Transactions!$C:$C,Transactions!$A:$A,">="&DATE(YEAR($A24),MONTH($A24),1),Transactions!$A:$A,"<="&EOMONTH($A24,0)) -> 0 | G24: =SUM($F$2:F24) -> 61752.649 | H24: =B24+F24 -> 87613.899 | I24: =(2%/12)*AVERAGE(B24,H24) -> 146.02316 | J24: =MAX((F24)*20%,0) -> 0 | K24: =I24+J24 -> 146.02316 | L24: =SUM(K$2:$K24) -> 15104.956 | N24: =L24-SUM($M$2:M24) -> 15104.956 | O24: =C24+F24-K24 -> 72508.943 | P24: =_xlfn.XLOOKUP(A24,'Client Management'!$D$3:$AB$3,'Client Management'!$D$94:$AB$94) -> 197.07705 | Q24: =H24/P24 -> 444.56672 | R24: =O24/P24 -> 367.9218 | S24: =H24/B24 -1 -> 0 | T24: =O24/B24 -1 -> -0.17240365

Sheet Client Management
A1: Monthly Summary
D3: 45292 | E3: 45323 | F3: 45352 | G3: 45383 | H3: 45413 | I3: 45444 | J3: 45474 | K3: 45505 | L3: 45536 | M3: 45566 | N3: 45597 | O3: 45627 | P3: 45658 | Q3: 45689 | R3: 45717 | S3: 45748 | T3: 45778 | U3: 45809 | V3: 45839 | W3: 45870 | X3: 45901 | Y3: 45931 | Z3: 45962 | AA3: 45992 | AB3: 46023
A5: x | B5: Investor Distribution
B6: William Collard | C6: =SUM(D6:XFD6) -> 5241.3892 | D6: =(D67/D$94)*_xlfn.XLOOKUP(D$3,'Fund Management'!$A:$A,'Fund Management'!$F:$F) -> 197.16814 | E6: =(E67/E$94)*_xlfn.XLOOKUP(E$3,'Fund Management'!$A:$A,'Fund Management'!$F:$F) -> 26.803683 | F6: =(F67/F$94)*_xlfn.XLOOKUP(F$3,'Fund Management'!$A:$A,'Fund Management'!$F:$F) -> -95.638811 | G6: =(G67/G$94)*_xlfn.XLOOKUP(G$3,'Fund Management'!$A:$A,'Fund Management'!$F:$F) -> -341.80536 | H6: =(H67/H$94)*_xlfn.XLOOKUP(H$3,'Fund Management'!$A:$A,'Fund Management'!$F:$F) -> -100.20387 | I6: =(I67/I$94)*_xlfn.XLOOKUP(I$3,'Fund Management'!$A:$A,'Fund Management'!$F:$F) -> 42.838218 | J6: =(J67/J$94)*_xlfn.XLOOKUP(J$3,'Fund Management'!$A:$A,'Fund Management'!$F:$F) -> 21.813288 | K6: =(K67/K$94)*_xlfn.XLOOKUP(K$3,'Fund Management'!$A:$A,'Fund Management'!$F:$F) -> 65.736363 | ... Z6: =(Z67/Z$94)*_xlfn.XLOOKUP(Z$3,'Fund Management'!$A:$A,'Fund Management'!$F:$F) -> 0
B7: Mashooq Nasser | C7: =SUM(D7:XFD7) -> 5519.6224 | D7: =(D68/D$94)*_xlfn.XLOOKUP(D$3,'Fund Management'!$A:$A,'Fund Management'!$F:$F) -> 179.16189 | E7: =(E68/E$94)*_xlfn.XLOOKUP(E$3,'Fund Management'!$A:$A,'Fund Management'!$F:$F) -> 21.377308 | F7: =(F68/F$94)*_xlfn.XLOOKUP(F$3,'Fund Management'!$A:$A,'Fund Management'!$F:$F) -> -76.276844 | G7: =(G68/G$94)*_xlfn.XLOOKUP(G$3,'Fund Management'!$A:$A,'Fund Management'!$F:$F) -> -272.60726 | H7: =(H68/H$94)*_xlfn.XLOOKUP(H$3,'Fund Management'!$A:$A,'Fund Management'!$F:$F) -> -79.917711 | I7: =(I68/I$94)*_xlfn.XLOOKUP(I$3,'Fund Management'!$A:$A,'Fund Management'!$F:$F) -> 34.16567 | J7: =(J68/J$94)*_xlfn.XLOOKUP(J$3,'Fund Management'!$A:$A,'Fund Management'!$F:$F) -> 17.397213 | K7: =(K68/K$94)*_xlfn.XLOOKUP(K$3,'Fund Management'!$A:$A,'Fund Management'!$F:$F) -> 52.428113 | ... Z7: =(Z68/Z$94)*_xlfn.XLOOKUP(Z$3,'Fund Management'!$A:$A,'Fund Management'!$F:$F) -> 0
B8: Jeroen Cox | C8: =SUM(D8:XFD8) -> 1039.203 | D8: =(D69/D$94)*_xlfn.XLOOKUP(D$3,'Fund Management'!$A:$A,'Fund Management'!$F:$F) -> 18.006253 | E8: =(E69/E$94)*_xlfn.XLOOKUP(E$3,'Fund Management'!$A:$A,'Fund Management'!$F:$F) -> 5.4263745 | F8: =(F69/F$94)*_xlfn.XLOOKUP(F$3,'Fund Management'!$A:$A,'Fund Management'!$F:$F) -> -19.361967 | G8: =(G69/G$94)*_xlfn.XLOOKUP(G$3,'Fund Management'!$A:$A,'Fund Management'!$F:$F) -> -69.198099 | H8: =(H69/H$94)*_xlfn.XLOOKUP(H$3,'Fund Management'!$A:$A,'Fund Management'!$F:$F) -> -20.286157 | I8: =(I69/I$94)*_xlfn.XLOOKUP(I$3,'Fund Management'!$A:$A,'Fund Management'!$F:$F) -> 8.6725476 | J8: =(J69/J$94)*_xlfn.XLOOKUP(J$3,'Fund Management'!$A:$A,'Fund Management'!$F:$F) -> 4.4160749 | K8: =(K69/K$94)*_xlfn.XLOOKUP(K$3,'Fund Management'!$A:$A,'Fund Management'!$F:$F) -> 13.308251 | ... Z8: =(Z69/Z$94)*_xlfn.XLOOKUP(Z$3,'Fund Management'!$A:$A,'Fund Management'!$F:$F) -> 0
B9: Alex Grewe | C9: =SUM(D9:XFD9) -> 714.44761 | D9: =(D70/D$94)*_xlfn.XLOOKUP(D$3,'Fund Management'!$A:$A,'Fund Management'!$F:$F) -> 18.006253 | E9: =(E70/E$94)*_xlfn.XLOOKUP(E$3,'Fund Management'!$A:$A,'Fund Management'!$F:$F) -> 3.7007088 | F9: =(F70/F$94)*_xlfn.XLOOKUP(F$3,'Fund Management'!$A:$A,'Fund Management'!$F:$F) -> -13.204581 | G9: =(G70/G$94)*_xlfn.XLOOKUP(G$3,'Fund Management'!$A:$A,'Fund Management'!$F:$F) -> -47.192101 | H9: =(H70/H$94)*_xlfn.XLOOKUP(H$3,'Fund Management'!$A:$A,'Fund Management'!$F:$F) -> -13.834865 | I9: =(I70/I$94)*_xlfn.XLOOKUP(I$3,'Fund Management'!$A:$A,'Fund Management'!$F:$F) -> 5.9145518 | J9: =(J70/J$94)*_xlfn.XLOOKUP(J$3,'Fund Management'!$A:$A,'Fund Management'!$F:$F) -> 3.0116991 | K9: =(K70/K$94)*_xlfn.XLOOKUP(K$3,'Fund Management'!$A:$A,'Fund Management'!$F:$F) -> 9.0760341 | ... Z9: =(Z70/Z$94)*_xlfn.XLOOKUP(Z$3,'Fund Management'!$A:$A,'Fund Management'!$F:$F) -> 0
B10: Jiani Chen | C10: =SUM(D10:XFD10) -> 552.06994 | D10: =(D71/D$94)*_xlfn.XLOOKUP(D$3,'Fund Management'!$A:$A,'Fund Management'!$F:$F) -> 18.006253 | E10: =(E71/E$94)*_xlfn.XLOOKUP(E$3,'Fund Management'!$A:$A,'Fund Management'!$F:$F) -> 2.8378759 | F10: =(F71/F$94)*_xlfn.XLOOKUP(F$3,'Fund Management'!$A:$A,'Fund Management'!$F:$F) -> -10.125888 | G10: =(G71/G$94)*_xlfn.XLOOKUP(G$3,'Fund Management'!$A:$A,'Fund Management'!$F:$F) -> -36.189102 | H10: =(H71/H$94)*_xlfn.XLOOKUP(H$3,'Fund Management'!$A:$A,'Fund Management'!$F:$F) -> -10.609219 | I10: =(I71/I$94)*_xlfn.XLOOKUP(I$3,'Fund Management'!$A:$A,'Fund Management'!$F:$F) -> 4.5355539 | J10: =(J71/J$94)*_xlfn.XLOOKUP(J$3,'Fund Management'!$A:$A,'Fund Management'!$F:$F) -> 2.3095112 | K10: =(K71/K$94)*_xlfn.XLOOKUP(K$3,'Fund Management'!$A:$A,'Fund Management'!$F:$F) -> 6.9599258 | ... Z10: =(Z71/Z$94)*_xlfn.XLOOKUP(Z$3,'Fund Management'!$A:$A,'Fund Management'!$F:$F) -> 0
B11: Suren Rana | C11: =SUM(D11:XFD11) -> 361.28411 | D11: =(D72/D$94)*_xlfn.XLOOKUP(D$3,'Fund Management'!$A:$A,'Fund Management'!$F:$F) -> 9.0031266 | E11: =(E72/E$94)*_xlfn.XLOOKUP(E$3,'Fund Management'!$A:$A,'Fund Management'!$F:$F) -> 0.98752153 | F11: =(F72/F$94)*_xlfn.XLOOKUP(F$3,'Fund Management'!$A:$A,'Fund Management'!$F:$F) -> -3.5235973 | G11: =(G72/G$94)*_xlfn.XLOOKUP(G$3,'Fund Management'!$A:$A,'Fund Management'!$F:$F) -> -12.593051 | H11: =(H72/H$94)*_xlfn.XLOOKUP(H$3,'Fund Management'!$A:$A,'Fund Management'!$F:$F) -> -3.6917866 | I11: =(I72/I$94)*_xlfn.XLOOKUP(I$3,'Fund Management'!$A:$A,'Fund Management'!$F:$F) -> 1.578278 | J11: =(J72/J$94)*_xlfn.XLOOKUP(J$3,'Fund Management'!$A:$A,'Fund Management'!$F:$F) -> 0.80366163 | K11: =(K72/K$94)*_xlfn.XLOOKUP(K$3,'Fund Management'!$A:$A,'Fund Management'!$F:$F) -> 2.4219088 | ... Z11: =(Z72/Z$94)*_xlfn.XLOOKUP(Z$3,'Fund Management'!$A:$A,'Fund Management'!$F:$F) -> 0
B12: Alasgar Mammedov | C12: =SUM(D12:XFD12) -> 519.60148 | D12: =(D73/D$94)*_xlfn.XLOOKUP(D$3,'Fund Management'!$A:$A,'Fund Management'!$F:$F) -> 9.0031266 | E12: =(E73/E$94)*_xlfn.XLOOKUP(E$3,'Fund Management'!$A:$A,'Fund Management'!$F:$F) -> 2.7131873 | F12: =(F73/F$94)*_xlfn.XLOOKUP(F$3,'Fund Management'!$A:$A,'Fund Management'!$F:$F) -> -9.6809833 | G12: =(G73/G$94)*_xlfn.XLOOKUP(G$3,'Fund Management'!$A:$A,'Fund Management'!$F:$F) -> -34.59905 | H12: =(H73/H$94)*_xlfn.XLOOKUP(H$3,'Fund Management'!$A:$A,'Fund Management'!$F:$F) -> -10.143079 | I12: =(I73/I$94)*_xlfn.XLOOKUP(I$3,'Fund Management'!$A:$A,'Fund Management'!$F:$F) -> 4.3362738 | J12: =(J73/J$94)*_xlfn.XLOOKUP(J$3,'Fund Management'!$A:$A,'Fund Management'!$F:$F) -> 2.2080374 | K12: =(K73/K$94)*_xlfn.XLOOKUP(K$3,'Fund Management'!$A:$A,'Fund Management'!$F:$F) -> 6.6541253 | ... Z12: =(Z73/Z$94)*_xlfn.XLOOKUP(Z$3,'Fund Management'!$A:$A,'Fund Management'!$F:$F) -> 0
B13: Pierre-Alexis Maillart | C13: =SUM(D13:XFD13) -> -36.569172 | D13: =(D74/D$94)*_xlfn.XLOOKUP(D$3,'Fund Management'!$A:$A,'Fund Management'!$F:$F) -> 9.0031266 | E13: =(E74/E$94)*_xlfn.XLOOKUP(E$3,'Fund Management'!$A:$A,'Fund Management'!$F:$F) -> 0.98752153 | F13: =(F74/F$94)*_xlfn.XLOOKUP(F$3,'Fund Management'!$A:$A,'Fund Management'!$F:$F) -> -3.5235973 | G13: =(G74/G$94)*_xlfn.XLOOKUP(G$3,'Fund Management'!$A:$A,'Fund Management'!$F:$F) -> -12.593051 | H13: =(H74/H$94)*_xlfn.XLOOKUP(H$3,'Fund Management'!$A:$A,'Fund Management'!$F:$F) -> -3.6917866 | I13: =(I74/I$94)*_xlfn.XLOOKUP(I$3,'Fund Management'!$A:$A,'Fund Management'!$F:$F) -> 1.578278 | J13: =(J74/J$94)*_xlfn.XLOOKUP(J$3,'Fund Management'!$A:$A,'Fund Management'!$F:$F) -> 0.80366163 | K13: =(K74/K$94)*_xlfn.XLOOKUP(K$3,'Fund Management'!$A:$A,'Fund Management'!$F:$F) -> 2.4219088 | ... Z13: =(Z74/Z$94)*_xlfn.XLOOKUP(Z$3,'Fund Management'!$A:$A,'Fund Management'!$F:$F) -> 0
B14: Suyash Gyawali | C14: =SUM(D14:XFD14) -> 354.59404 | D14: =(D75/D$94)*_xlfn.XLOOKUP(D$3,'Fund Management'!$A:$A,'Fund Management'!$F:$F) -> 9.0031266 | E14: =(E75/E$94)*_xlfn.XLOOKUP(E$3,'Fund Management'!$A:$A,'Fund Management'!$F:$F) -> 0.98752153 | F14: =(F75/F$94)*_xlfn.XLOOKUP(F$3,'Fund Management'!$A:$A,'Fund Management'!$F:$F) -> -6.56861 | G14: =(G75/G$94)*_xlfn.XLOOKUP(G$3,'Fund Management'!$A:$A,'Fund Management'!$F:$F) -> -23.47568 | H14: =(H75/H$94)*_xlfn.XLOOKUP(H$3,'Fund Management'!$A:$A,'Fund Management'!$F:$F) -> -6.8821447 | I14: =(I75/I$94)*_xlfn.XLOOKUP(I$3,'Fund Management'!$A:$A,'Fund Management'!$F:$F) -> 2.9421899 | J14: =(J75/J$94)*_xlfn.XLOOKUP(J$3,'Fund Management'!$A:$A,'Fund Management'!$F:$F) -> 1.4981677 | K14: =(K75/K$94)*_xlfn.XLOOKUP(K$3,'Fund Management'!$A:$A,'Fund Management'!$F:$F) -> 4.5148673 | ... Z14: =(Z75/Z$94)*_xlfn.XLOOKUP(Z$3,'Fund Management'!$A:$A,'Fund Management'!$F:$F) -> 0
B15: Louis Durance | C15: =SUM(D15:XFD15) -> 357.22381 | D15: =(D76/D$94)*_xlfn.XLOOKUP(D$3,'Fund Management'!$A:$A,'Fund Management'!$F:$F) -> 9.0031266 | E15: =(E76/E$94)*_xlfn.XLOOKUP(E$3,'Fund Management'!$A:$A,'Fund Management'!$F:$F) -> 1.8503544 | F15: =(F76/F$94)*_xlfn.XLOOKUP(F$3,'Fund Management'!$A:$A,'Fund Management'!$F:$F) -> -6.6022903 | G15: =(G76/G$94)*_xlfn.XLOOKUP(G$3,'Fund Management'!$A:$A,'Fund Management'!$F:$F) -> -23.596051 | H15: =(H76/H$94)*_xlfn.XLOOKUP(H$3,'Fund Management'!$A:$A,'Fund Management'!$F:$F) -> -6.9174326 | I15: =(I76/I$94)*_xlfn.XLOOKUP(I$3,'Fund Management'!$A:$A,'Fund Management'!$F:$F) -> 2.9572759 | J15: =(J76/J$94)*_xlfn.XLOOKUP(J$3,'Fund Management'!$A:$A,'Fund Management'!$F:$F) -> 1.5058495 | K15: =(K76/K$94)*_xlfn.XLOOKUP(K$3,'Fund Management'!$A:$A,'Fund Management'!$F:$F) -> 4.538017 | ... Z15: =(Z76/Z$94)*_xlfn.XLOOKUP(Z$3,'Fund Management'!$A:$A,'Fund Management'!$F:$F) -> 0
B16: Alex Kush | C16: =SUM(D16:XFD16) -> 1818.6229 | D16: =(D77/D$94)*_xlfn.XLOOKUP(D$3,'Fund Management'!$A:$A,'Fund Management'!$F:$F) -> 9.0031266 | E16: =(E77/E$94)*_xlfn.XLOOKUP(E$3,'Fund Management'!$A:$A,'Fund Management'!$F:$F) -> 9.6158502 | F16: =(F77/F$94)*_xlfn.XLOOKUP(F$3,'Fund Management'!$A:$A,'Fund Management'!$F:$F) -> -34.310527 | G16: =(G77/G$94)*_xlfn.XLOOKUP(G$3,'Fund Management'!$A:$A,'Fund Management'!$F:$F) -> -122.62304 | H16: =(H77/H$94)*_xlfn.XLOOKUP(H$3,'Fund Management'!$A:$A,'Fund Management'!$F:$F) -> -35.948246 | I16: =(I77/I$94)*_xlfn.XLOOKUP(I$3,'Fund Management'!$A:$A,'Fund Management'!$F:$F) -> 15.368257 | J16: =(J77/J$94)*_xlfn.XLOOKUP(J$3,'Fund Management'!$A:$A,'Fund Management'!$F:$F) -> 7.8255406 | K16: =(K77/K$94)*_xlfn.XLOOKUP(K$3,'Fund Management'!$A:$A,'Fund Management'!$F:$F) -> 23.582992 | ... Z16: =(Z77/Z$94)*_xlfn.XLOOKUP(Z$3,'Fund Management'!$A:$A,'Fund Management'!$F:$F) -> 0
B17: Tristan Collard | C17: =SUM(D17:XFD17) -> 382.29754 | D17: =(D78/D$94)*_xlfn.XLOOKUP(D$3,'Fund Management'!$A:$A,'Fund Management'!$F:$F) -> 9.0031266 | E17: =(E78/E$94)*_xlfn.XLOOKUP(E$3,'Fund Management'!$A:$A,'Fund Management'!$F:$F) -> 1.8503544 | F17: =(F78/F$94)*_xlfn.XLOOKUP(F$3,'Fund Management'!$A:$A,'Fund Management'!$F:$F) -> -6.6022903 | G17: =(G78/G$94)*_xlfn.XLOOKUP(G$3,'Fund Management'!$A:$A,'Fund Management'!$F:$F) -> -23.596051 | H17: =(H78/H$94)*_xlfn.XLOOKUP(H$3,'Fund Management'!$A:$A,'Fund Management'!$F:$F) -> -6.9174326 | I17: =(I78/I$94)*_xlfn.XLOOKUP(I$3,'Fund Management'!$A:$A,'Fund Management'!$F:$F) -> 2.9572759 | J17: =(J78/J$94)*_xlfn.XLOOKUP(J$3,'Fund Management'!$A:$A,'Fund Management'!$F:$F) -> 1.5058495 | K17: =(K78/K$94)*_xlfn.XLOOKUP(K$3,'Fund Management'!$A:$A,'Fund Management'!$F:$F) -> 4.538017 | ... Z17: =(Z78/Z$94)*_xlfn.XLOOKUP(Z$3,'Fund Management'!$A:$A,'Fund Management'!$F:$F) -> 0
... B31: Asad Nasser | C31: =SUM(D31:XFD31) -> 3028.2498 | D31: =(D92/D$94)*_xlfn.XLOOKUP(D$3,'Fund Management'!$A:$A,'Fund Management'!$F:$F) -> 0 | E31: =(E92/E$94)*_xlfn.XLOOKUP(E$3,'Fund Management'!$A:$A,'Fund Management'!$F:$F) -> 0 | F31: =(F92/F$94)*_xlfn.XLOOKUP(F$3,'Fund Management'!$A:$A,'Fund Management'!$F:$F) -> 0 | G31: =(G92/G$94)*_xlfn.XLOOKUP(G$3,'Fund Management'!$A:$A,'Fund Management'!$F:$F) -> 0 | H31: =(H92/H$94)*_xlfn.XLOOKUP(H$3,'Fund Management'!$A:$A,'Fund Management'!$F:$F) -> 0 | I31: =(I92/I$94)*_xlfn.XLOOKUP(I$3,'Fund Management'!$A:$A,'Fund Management'!$F:$F) -> 0 | J31: =(J92/J$94)*_xlfn.XLOOKUP(J$3,'Fund Management'!$A:$A,'Fund Management'!$F:$F) -> 0 | K31: =(K92/K$94)*_xlfn.XLOOKUP(K$3,'Fund Management'!$A:$A,'Fund Management'!$F:$F) -> 0 | ... Z31: =(Z92/Z$94)*_xlfn.XLOOKUP(Z$3,'Fund Management'!$A:$A,'Fund Management'!$F:$F) -> 0
B33: Total | D33: =SUM(D6:D31) -> 493.37068 | E33: =SUM(E6:E32) -> 108.99225 | F33: =SUM(F6:F32) -> -919.41183 | G33: =SUM(G6:G32) -> -3400.7297 | H33: =SUM(H6:H32) -> -996.96 | I33: =SUM(I6:I32) -> 486.61431 | J33: =SUM(J6:J32) -> 247.78477 | K33: =SUM(K6:K32) -> 746.72236 | L33: =SUM(L6:L32) -> -931.9425 | ... Z33: =SUM(Z6:Z32) -> 0
D34: =IF(D33=_xlfn.XLOOKUP(D$3,'Fund Management'!$A:$A,'Fund Management'!$F:$F),"OK","NOK") -> OK | E34: =IF(E33=_xlfn.XLOOKUP(E$3,'Fund Management'!$A:$A,'Fund Management'!$F:$F),"OK","NOK") -> OK | F34: =IF(F33=_xlfn.XLOOKUP(F$3,'Fund Management'!$A:$A,'Fund Management'!$F:$F),"OK","NOK") -> OK | G34: =IF(G33=_xlfn.XLOOKUP(G$3,'Fund Management'!$A:$A,'Fund Management'!$F:$F),"OK","NOK") -> NOK | H34: =IF(H33=_xlfn.XLOOKUP(H$3,'Fund Management'!$A:$A,'Fund Management'!$F:$F),"OK","NOK") -> OK | I34: =IF(I33=_xlfn.XLOOKUP(I$3,'Fund Management'!$A:$A,'Fund Management'!$F:$F),"OK","NOK") -> OK | J34: =IF(J33=_xlfn.XLOOKUP(J$3,'Fund Management'!$A:$A,'Fund Management'!$F:$F),"OK","NOK") -> OK | K34: =IF(K33=_xlfn.XLOOKUP(K$3,'Fund Management'!$A:$A,'Fund Management'!$F:$F),"OK","NOK") -> OK | ... AB34: =IF(AB33=_xlfn.XLOOKUP(AB$3,'Fund Management'!$A:$A,'Fund Management'!$F:$F),"OK","NOK") -> #N/A
A36: x | B36: Investor Net Deposit
B37: William Collard | C37: =SUM(D37:XFD37) -> 1524.1 | D37: 1199.68 | E37: 324.42
B38: Mashooq Nasser | C38: =SUM(D38:XFD38) -> 10198.26 | D38: 1090.12 | E38: 108.14 | U38: 9000
B39: Jeroen Cox | C39: =SUM(D39:XFD39) -> 325.84 | D39: 109.56 | E39: 216.28
B40: Alex Grewe | C40: =SUM(D40:XFD40) -> 217.7 | D40: 109.56 | E40: 108.14
B41: Jiani Chen | C41: =SUM(D41:XFD41) -> 163.63 | D41: 109.56 | E41: 54.07
B42: Suren Rana | C42: =SUM(D42:XFD42) -> 1189.08 | D42: 54.78 | E42: 0 | T42: 1134.3
B43: Alasgar Mammedov | C43: =SUM(D43:XFD43) -> 162.92 | D43: 54.78 | E43: 108.14
B44: Pierre-Alexis Maillart | C44: =SUM(D44:XFD44) -> -52.78 | D44: 54.78 | E44: 0 | R44: -107.56
B45: Suyash Gyawali | C45: =SUM(D45:XFD45) -> 108.85 | D45: 54.78 | E45: 0 | F45: 54.07
B46: Louis Durance | C46: =SUM(D46:XFD46) -> 108.85 | D46: 54.78 | E46: 54.07
B47: Alex Kush | C47: =SUM(D47:XFD47) -> 595.48 | D47: 54.78 | E47: 540.7
B48: Tristan Collard | C48: =SUM(D48:XFD48) -> 280.14 | D48: 54.78 | E48: 54.07 | U48: 171.29
B49: Karina Lau | C49: =SUM(D49:XFD49) -> 54.07 | D49: 0 | E49: 54.07
B50: Mitch Feij | C50: =SUM(D50:XFD50) -> -75.74 | D50: 0 | E50: 324.42 | P50: -400.16
B51: Philipp Dorfner | C51: =SUM(D51:XFD51) -> -1120.75 | D51: 0 | E51: 540.7 | Y51: -1661.45
B52: Paolo Shamoon | C52: =SUM(D52:XFD52) -> 248.72 | D52: 0 | E52: 248.72
B53: Jeremy Duckert | C53: =SUM(D53:XFD53) -> 162.21 | D53: 0 | E53: 162.21
B54: Casper Adam | C54: =SUM(D54:XFD54) -> 216.28 | D54: 0 | E54: 216.28
B55: Aman Karim | C55: =SUM(D55:XFD55) -> 216.28 | D55: 0 | E55: 216.28
B56: Benjamin Champion | C56: =SUM(D56:XFD56) -> 108.14 | D56: 0 | E56: 108.14
B57: Norbert Bruls | C57: =SUM(D57:XFD57) -> 2162.6 | F57: 2162.6
...

Sheet Transactions
A1: date | B1: symbol | C1: pnl
A2: 45314 | B2: NIFTY50 | C2: 126.97409
A3: 45316 | B3: TSLA 26JAN24 217.5 C | C3: -1422.7021
A4: 45316 | B4: TSLA 26JAN24 202.5 P | C4: 2956.7705
A5: 45322 | B5: AMD 02FEB24 175 C | C5: -772.09691
A6: 45322 | B6: AMD 02FEB24 190 C | C6: 354.50062
A7: 45322 | B7: SBUX 02FEB24 90 P | C7: 633.01203
A8: 45322 | B8: SBUX 02FEB24 95 P | C8: -1326.9868
A9: 45322 | B9: SPY 02FEB24 487.5 C | C9: -56.100846
A10: 45324 | B10: SPY 02FEB24 487.5 P | C10: -286.04935
A11: 45328 | B11: NIFTYBANK | C11: 395.0416
A12: 45355 | B12: MCLJ4 | C12: -348.16
A13: 45357 | B13: ORCL 08MAR24 112 C | C13: -78.587674
... A136: 45895 | B136: ZQM6 | C136: 1301.625

Sheet NAV Calculation
A1: date | B1: gross fund value | C1: gross net value | D1: unrealized pnl | E1: shares | F1: gross nav | G1: net nav
A2: 45616 | B2: =_xlfn.XLOOKUP(EOMONTH(A2,-1)+1,'Fund Management'!A:A,'Fund Management'!H:H) -> 23835.686 | C2: =_xlfn.XLOOKUP(EOMONTH(A2,-1)+1,'Fund Management'!A:A,'Fund Management'!O:O) -> 21171.215 | D2: =_xlfn.XLOOKUP(A2,'Unrealized PnL'!A:A,'Unrealized PnL'!E:E) -> 8300 | E2: =_xlfn.XLOOKUP(EOMONTH(A2,-1)+1,'Fund Management'!A:A,'Fund Management'!P:P) -> 168.89757 | F2: =(B2+D2)/E2 -> 190.26731

Sheet Unrealized PnL
A1: date | B1: symbol | C1: currency | D1: unrealizedPnL | E1: unrealizedPnL_usd
A2: 45616 | E2: 8300

Sheet lkp table
A1: Symbol
A2: EZA
A3: EWZ
A4: EIDO
A5: INDA
A6: EMLC
A7: HYEM
A8: IBCID789044754
A9: TLT
